2018-05-04 10:26:29,716 ERROR: Exception on /reset_password_request [POST] [in /Users/fimasik/.virtualenvs/python-flask_tutor/lib/python3.6/site-packages/flask/app.py:1560]
Traceback (most recent call last):
  File "/Users/fimasik/.virtualenvs/python-flask_tutor/lib/python3.6/site-packages/flask/app.py", line 1982, in wsgi_app
    response = self.full_dispatch_request()
  File "/Users/fimasik/.virtualenvs/python-flask_tutor/lib/python3.6/site-packages/flask/app.py", line 1614, in full_dispatch_request
    rv = self.handle_user_exception(e)
  File "/Users/fimasik/.virtualenvs/python-flask_tutor/lib/python3.6/site-packages/flask/app.py", line 1517, in handle_user_exception
    reraise(exc_type, exc_value, tb)
  File "/Users/fimasik/.virtualenvs/python-flask_tutor/lib/python3.6/site-packages/flask/_compat.py", line 33, in reraise
    raise value
  File "/Users/fimasik/.virtualenvs/python-flask_tutor/lib/python3.6/site-packages/flask/app.py", line 1612, in full_dispatch_request
    rv = self.dispatch_request()
  File "/Users/fimasik/.virtualenvs/python-flask_tutor/lib/python3.6/site-packages/flask/app.py", line 1598, in dispatch_request
    return self.view_functions[rule.endpoint](**req.view_args)
  File "/Users/fimasik/Projects/python-flask_tutor/microblog/app/routes.py", line 196, in reset_password_request
    send_password_reset_email(user)
  File "/Users/fimasik/Projects/python-flask_tutor/microblog/app/email.py", line 21, in send_password_reset_email
    user=user, token=token),
  File "/Users/fimasik/.virtualenvs/python-flask_tutor/lib/python3.6/site-packages/flask/templating.py", line 133, in render_template
    return _render(ctx.app.jinja_env.get_or_select_template(template_name_or_list),
  File "/Users/fimasik/.virtualenvs/python-flask_tutor/lib/python3.6/site-packages/jinja2/environment.py", line 869, in get_or_select_template
    return self.get_template(template_name_or_list, parent, globals)
  File "/Users/fimasik/.virtualenvs/python-flask_tutor/lib/python3.6/site-packages/jinja2/environment.py", line 830, in get_template
    return self._load_template(name, self.make_globals(globals))
  File "/Users/fimasik/.virtualenvs/python-flask_tutor/lib/python3.6/site-packages/jinja2/environment.py", line 804, in _load_template
    template = self.loader.load(self, name, globals)
  File "/Users/fimasik/.virtualenvs/python-flask_tutor/lib/python3.6/site-packages/jinja2/loaders.py", line 113, in load
    source, filename, uptodate = self.get_source(environment, name)
  File "/Users/fimasik/.virtualenvs/python-flask_tutor/lib/python3.6/site-packages/flask/templating.py", line 57, in get_source
    return self._get_source_fast(environment, template)
  File "/Users/fimasik/.virtualenvs/python-flask_tutor/lib/python3.6/site-packages/flask/templating.py", line 85, in _get_source_fast
    raise TemplateNotFound(template)
jinja2.exceptions.TemplateNotFound: email/reset_password.txt
2018-05-04 10:31:47,036 INFO: Microblog startup [in /Users/fimasik/Projects/python-flask_tutor/microblog/app/__init__.py:53]
2018-05-04 10:32:07,707 ERROR: Exception on /reset_password_request [POST] [in /Users/fimasik/.virtualenvs/python-flask_tutor/lib/python3.6/site-packages/flask/app.py:1560]
Traceback (most recent call last):
  File "/Users/fimasik/.virtualenvs/python-flask_tutor/lib/python3.6/site-packages/flask/app.py", line 1982, in wsgi_app
    response = self.full_dispatch_request()
  File "/Users/fimasik/.virtualenvs/python-flask_tutor/lib/python3.6/site-packages/flask/app.py", line 1614, in full_dispatch_request
    rv = self.handle_user_exception(e)
  File "/Users/fimasik/.virtualenvs/python-flask_tutor/lib/python3.6/site-packages/flask/app.py", line 1517, in handle_user_exception
    reraise(exc_type, exc_value, tb)
  File "/Users/fimasik/.virtualenvs/python-flask_tutor/lib/python3.6/site-packages/flask/_compat.py", line 33, in reraise
    raise value
  File "/Users/fimasik/.virtualenvs/python-flask_tutor/lib/python3.6/site-packages/flask/app.py", line 1612, in full_dispatch_request
    rv = self.dispatch_request()
  File "/Users/fimasik/.virtualenvs/python-flask_tutor/lib/python3.6/site-packages/flask/app.py", line 1598, in dispatch_request
    return self.view_functions[rule.endpoint](**req.view_args)
  File "/Users/fimasik/Projects/python-flask_tutor/microblog/app/routes.py", line 196, in reset_password_request
    send_password_reset_email(user)
  File "/Users/fimasik/Projects/python-flask_tutor/microblog/app/email.py", line 21, in send_password_reset_email
    user=user, token=token),
  File "/Users/fimasik/.virtualenvs/python-flask_tutor/lib/python3.6/site-packages/flask/templating.py", line 133, in render_template
    return _render(ctx.app.jinja_env.get_or_select_template(template_name_or_list),
  File "/Users/fimasik/.virtualenvs/python-flask_tutor/lib/python3.6/site-packages/jinja2/environment.py", line 869, in get_or_select_template
    return self.get_template(template_name_or_list, parent, globals)
  File "/Users/fimasik/.virtualenvs/python-flask_tutor/lib/python3.6/site-packages/jinja2/environment.py", line 830, in get_template
    return self._load_template(name, self.make_globals(globals))
  File "/Users/fimasik/.virtualenvs/python-flask_tutor/lib/python3.6/site-packages/jinja2/environment.py", line 804, in _load_template
    template = self.loader.load(self, name, globals)
  File "/Users/fimasik/.virtualenvs/python-flask_tutor/lib/python3.6/site-packages/jinja2/loaders.py", line 113, in load
    source, filename, uptodate = self.get_source(environment, name)
  File "/Users/fimasik/.virtualenvs/python-flask_tutor/lib/python3.6/site-packages/flask/templating.py", line 57, in get_source
    return self._get_source_fast(environment, template)
  File "/Users/fimasik/.virtualenvs/python-flask_tutor/lib/python3.6/site-packages/flask/templating.py", line 85, in _get_source_fast
    raise TemplateNotFound(template)
jinja2.exceptions.TemplateNotFound: email/reset_password.txt
2018-05-04 10:33:07,597 INFO: Microblog startup [in /Users/fimasik/Projects/python-flask_tutor/microblog/app/__init__.py:53]
2018-05-04 10:34:48,084 ERROR: Exception on /reset_password_request [POST] [in /Users/fimasik/.virtualenvs/python-flask_tutor/lib/python3.6/site-packages/flask/app.py:1560]
Traceback (most recent call last):
  File "/Users/fimasik/.virtualenvs/python-flask_tutor/lib/python3.6/site-packages/flask/app.py", line 1982, in wsgi_app
    response = self.full_dispatch_request()
  File "/Users/fimasik/.virtualenvs/python-flask_tutor/lib/python3.6/site-packages/flask/app.py", line 1614, in full_dispatch_request
    rv = self.handle_user_exception(e)
  File "/Users/fimasik/.virtualenvs/python-flask_tutor/lib/python3.6/site-packages/flask/app.py", line 1517, in handle_user_exception
    reraise(exc_type, exc_value, tb)
  File "/Users/fimasik/.virtualenvs/python-flask_tutor/lib/python3.6/site-packages/flask/_compat.py", line 33, in reraise
    raise value
  File "/Users/fimasik/.virtualenvs/python-flask_tutor/lib/python3.6/site-packages/flask/app.py", line 1612, in full_dispatch_request
    rv = self.dispatch_request()
  File "/Users/fimasik/.virtualenvs/python-flask_tutor/lib/python3.6/site-packages/flask/app.py", line 1598, in dispatch_request
    return self.view_functions[rule.endpoint](**req.view_args)
  File "/Users/fimasik/Projects/python-flask_tutor/microblog/app/routes.py", line 196, in reset_password_request
    send_password_reset_email(user)
  File "/Users/fimasik/Projects/python-flask_tutor/microblog/app/email.py", line 23, in send_password_reset_email
    user=user, token=token))
  File "/Users/fimasik/Projects/python-flask_tutor/microblog/app/email.py", line 12, in send_email
    mail.send(msg)
  File "/Users/fimasik/.virtualenvs/python-flask_tutor/lib/python3.6/site-packages/flask_mail.py", line 491, in send
    with self.connect() as connection:
  File "/Users/fimasik/.virtualenvs/python-flask_tutor/lib/python3.6/site-packages/flask_mail.py", line 144, in __enter__
    self.host = self.configure_host()
  File "/Users/fimasik/.virtualenvs/python-flask_tutor/lib/python3.6/site-packages/flask_mail.py", line 165, in configure_host
    host.login(self.mail.username, self.mail.password)
  File "/usr/local/Cellar/python/3.6.5/Frameworks/Python.framework/Versions/3.6/lib/python3.6/smtplib.py", line 730, in login
    raise last_exception
  File "/usr/local/Cellar/python/3.6.5/Frameworks/Python.framework/Versions/3.6/lib/python3.6/smtplib.py", line 721, in login
    initial_response_ok=initial_response_ok)
  File "/usr/local/Cellar/python/3.6.5/Frameworks/Python.framework/Versions/3.6/lib/python3.6/smtplib.py", line 642, in auth
    raise SMTPAuthenticationError(code, resp)
smtplib.SMTPAuthenticationError: (535, b'5.7.8 Username and Password not accepted. Learn more at\n5.7.8  https://support.google.com/mail/?p=BadCredentials y137-v6sm54520lfd.96 - gsmtp')
2018-05-04 10:36:39,215 INFO: Microblog startup [in /Users/fimasik/Projects/python-flask_tutor/microblog/app/__init__.py:53]
